Workbook

Sheet Data
A1: 10 | B1: alpha | C1: 1.5 | D1: padded
A2: 20 | B2: beta | C2: 2.5 | D2: hello world
A3: 30 | B3: gamma | C3: 3.5 | D3: mIxEd CaSe
A4: 40 | B4: alpha | C4: 4.5
A5: 50 | B5: beta | C5: 5.5
A6: 60 | B6: gamma | C6: 6.5
A10: x | B10: y | C10: z
A11: 1 | B11: 2 | C11: 3

Sheet Calc
A1: SUM | B1: =SUM(Data!A1:A6) -> 210
A2: AVERAGE | B2: =AVERAGE(Data!A1:A6) -> 35
A3: COUNT | B3: =COUNT(Data!A1:A6) -> 6
A4: COUNTA | B4: =COUNTA(Data!B1:B6) -> 6
A5: MIN | B5: =MIN(Data!A1:A6) -> 10
A6: MAX | B6: =MAX(Data!A1:A6) -> 60
A7: ROUND | B7: =ROUND(2.567,2) -> 2.57
A8: ROUNDUP | B8: =ROUNDUP(2.111,2) -> 2.12
A9: ROUNDDOWN | B9: =ROUNDDOWN(2.999,2) -> 2.99
A10: ABS | B10: =ABS(-7.5) -> 7.5
A11: SQRT | B11: =SQRT(144) -> 12
A12: POWER | B12: =POWER(2,10) -> 1024
A13: MOD | B13: =MOD(17,5) -> 2
A14: SUMPRODUCT | B14: =SUMPRODUCT(Data!A1:A3,Data!C1:C3) -> 170
A15: SUBTOTAL | B15: =SUBTOTAL(9,Data!A1:A6) -> 210
A16: IF | B16: =IF(Data!A1>5,"yes","no") -> yes
A17: IFS | B17: =_xlfn.IFS(Data!A1>100,"big",Data!A1>5,"mid",TRUE(),"small") -> mid
A18: AND | B18: =AND(TRUE(),Data!A1=10) -> TRUE
A19: OR | B19: =OR(FALSE(),Data!A1=99) -> FALSE
A20: NOT | B20: =NOT(FALSE()) -> TRUE
A21: IFERROR | B21: =IFERROR(1/0,"safe") -> safe
A22: SWITCH | B22: =_xlfn.SWITCH(2,1,"one",2,"two","other") -> two
A23: VLOOKUP | B23: =VLOOKUP("beta",Data!B1:C6,2,FALSE()) -> 2.5
A24: HLOOKUP | B24: =HLOOKUP("y",Data!A10:C11,2,FALSE()) -> 2
A25: XLOOKUP | B25: =_xlfn.XLOOKUP("gamma",Data!B1:B6,Data!C1:C6) -> 3.5
A26: INDEX | B26: =INDEX(Data!A1:A6,3) -> 30
A27: MATCH | B27: =MATCH(40,Data!A1:A6,0) -> 4
A28: OFFSET | B28: =OFFSET(Data!A1,2,0) -> 30
A29: INDIRECT | B29: =INDIRECT("Data!A2") -> 20
A30: CHOOSE | B30: =CHOOSE(3,"a","b","c") -> c
A31: CONCAT | B31: =_xlfn.CONCAT(Data!B1,"-",Data!B2) -> alpha-beta
A32: TEXTJOIN | B32: =_xlfn.TEXTJOIN(",",TRUE(),Data!B1:B3) -> alpha,beta,gamma
A33: LEFT | B33: =LEFT(Data!D2,5) -> hello
A34: RIGHT | B34: =RIGHT(Data!D2,5) -> world
A35: MID | B35: =MID(Data!D2,7,5) -> world
A36: LEN | B36: =LEN(Data!D2) -> 11
A37: TRIM | B37: =TRIM(Data!D1) -> padded
A38: UPPER | B38: =UPPER(Data!D3) -> MIXED CASE
A39: LOWER | B39: =LOWER(Data!D3) -> mixed case
A40: PROPER | B40: =PROPER(Data!D3) -> Mixed Case
...
